Workbook

Sheet April
I3: Aster | S3: Bloom
C4: CL | D4: GL | E4: MN | F4: OM | G4: VV | H4: HC | I4: SW | J4: ST | K4: SP | L4: SRG | M4: WH | N4: BCM | O4: CPL | P4: MOM | Q4: MIM | R4: SR | S4: BBC | T4: BJP | U4: BMT | V4: BMC | W4: BMR | X4: BRV | Y4: BST | Z4: BGW | AA4: BHR | AB4: BJB | AC4: BLV | AD4: BRC | AE4: BSD | AF4: BCT | AG4: BMS | AH4: IRO | AI4: IAM | AJ4: IAR | AK4: IEM | AL4: ILD | AM4: IPG | AN4: IPH | AO4: ITL | AP4: RBR | AQ4: RGO | AR4: RSM | AS4: RWB | AT4: RWG | AU4: RWH | AV4: RWL | AW4: RWW | AX4: MGS | AY4: MBC | AZ4: MCG | BA4: MQG | BB4: MRG | BC4: MVF
B5: SICK | C5: 2907.44 | D5: 34664.04 | E5: 33569.68 | F5: 3433.25 | G5: 8713.82 | H5: 1931.23 | I5: 23220.9 | J5: 40361.92 | K5: 58959.04 | L5: 13957.49 | M5: 42770.65 | N5: 17695.07 | O5: 3773.78 | P5: 2623.02 | Q5: 10375.57 | R5: 65.48 | S5: 24266.65 | T5: 25841.18 | U5: 15642.77 | V5: 36678.55 | W5: 13795.47 | X5: 13634.46 | Y5: 18758 | Z5: 28390.68 | AA5: 24680.55 | AB5: 17388.66 | AC5: 24198.6 | AD5: 33751.01 | AE5: 3963.18 | AF5: 1388.24 | AG5: 89.09 | AH5: 21774.87 | AI5: 7701.27 | AJ5: 27358.94 | AK5: 14284.62 | AL5: 1940.32 | AM5: 12039.02 | AN5: 5327.87 | AO5: 14658.13 | AP5: 22512.14 | AQ5: 20935 | AR5: 17517.84 | AS5: 30564.07 | AT5: 17411.27 | AU5: 12436.12 | AV5: 14901.12 | AW5: 15911.24 | AX5: 26265.94 | AY5: 12223.18 | AZ5: 17944.83 | BA5: 19810.34 | BB5: 11066.73 | BC5: 15080.25
B6: OT | C6: 425.86 | D6: 16631.41 | E6: 16765.86 | F6: 1441.01 | G6: 9459.56 | H6: 17.69 | I6: 13031.58 | J6: 2369.5 | K6: 21956.2 | L6: 21069.27 | M6: 9610.57 | N6: 46473.98 | O6: 8929.04 | P6: 6063.77 | Q6: 16729.67 | R6: 0 | S6: 14933.3 | T6: 8016.08 | U6: 3671.71 | V6: 10527.52 | W6: 3898.08 | X6: 20240.43 | Y6: 7181.3 | Z6: 131707.67 | AA6: 72545.1 | AB6: 36927.53 | AC6: 50832.9 | AD6: 40389.16 | AE6: 13487.37 | AF6: 0 | AG6: 0 | AH6: 80403.28 | AI6: 10432.81 | AJ6: 105165.54 | AK6: 14132.1 | AL6: 40921.82 | AM6: 27496.8 | AN6: 31843.59 | AO6: 88130.65 | AP6: 65228.87 | AQ6: 147194.64 | AR6: 88654.88 | AS6: 55308.02 | AT6: 47431.29 | AU6: 136503.59 | AV6: 77296.16 | AW6: 68396.83 | AX6: 44658.74 | AY6: 29807.78 | AZ6: 11332.16 | BA6: 30386.4 | BB6: 43046.4 | BC6: 68104.27
B7: Purchased Hours | C7: 38.18 | D7: 25900.87 | E7: 14411.53 | F7: 38.18 | G7: -1356.75 | H7: 423108.47 | I7: 38.18 | J7: 192.18 | K7: 10786.3 | L7: 38.18 | M7: 489.56 | N7: 128313.61 | O7: 144999.11 | P7: 130598 | Q7: 192960.77 | R7: 529241.41 | S7: 42 | T7: 2307.9 | U7: 22144.94 | V7: 38.18 | W7: 38.18 | X7: 2400 | Y7: 375.9 | Z7: 291937.3 | AA7: 190497.19 | AB7: 333411.53 | AC7: 286396.99 | AD7: 92885.18 | AE7: 83497.81 | AF7: 876512.88 | AG7: 908788.74 | AH7: 174592.13 | AI7: 29125.87 | AJ7: 172029.02 | AK7: 1294.84 | AL7: 48674.62 | AM7: 43941.11 | AN7: 57206.25 | AO7: 147032.95 | AP7: 98347.85 | AQ7: 86371.02 | AR7: 184127.84 | AS7: 125795.41 | AT7: 237686.33 | AU7: 143621.39 | AV7: 18830.83 | AW7: 10675.57 | AX7: 279696.95 | AY7: 80309.66 | AZ7: 172370.87 | BA7: 86086.11 | BB7: 263024.39 | BC7: 156201.36
B8: Supplies | C8: 659.9 | D8: 50413.65 | E8: 60313.68 | F8: 1483.49 | G8: 7891.96 | H8: 12485.28 | I8: 39206.13 | J8: 42273.21 | K8: 64643.08 | L8: 782.26 | M8: 40762.74 | N8: 12783.08 | O8: 12977.59 | P8: 12673.31 | Q8: 20630.6 | R8: 10586.18 | S8: 33641.53 | T8: 23659.49 | U8: 30071.29 | V8: 47655.41 | W8: 17201.12 | X8: 18296.63 | Y8: 28610.93 | Z8: 14186.27 | AA8: 17986.11 | AB8: 21384.69 | AC8: 25452.74 | AD8: 26860.3 | AE8: 5880.23 | AF8: 28054.99 | AG8: 25401.9 | AH8: 19953.31 | AI8: 1517.53 | AJ8: 23765.99 | AK8: 5657.13 | AL8: 16756.36 | AM8: 14242.58 | AN8: 6342.71 | AO8: 24382.07 | AP8: 24086.71 | AQ8: 15468.57 | AR8: 20285.62 | AS8: 55867.33 | AT8: 23379.96 | AU8: 20438.3 | AV8: 22051.09 | AW8: 18588.46 | AX8: 42982.85 | AY8: 15885.15 | AZ8: 27399.93 | BA8: 19252.94 | BB8: 15407.93 | BC8: 11046.05
B9: Capex | E9: 8908.2 | I9: 17387.85 | J9: 0 | K9: 22089.32 | L9: 6000.23 | M9: 58066.57 | N9: 116.63 | O9: 0 | P9: 0 | Q9: 2008.75 | R9: 0 | S9: 30048.03 | T9: 15513.8 | U9: 26695.43 | V9: 14074.36 | W9: 6139 | X9: 29394.75 | Y9: 0 | Z9: 55012.62 | AA9: 37798.95 | AB9: 31748.81 | AC9: 5652.02 | AD9: 51975 | AE9: 0 | AF9: 2098.73 | AG9: 6666.24 | AH9: 51120.46 | AI9: -15142 | AJ9: 9699.36 | AK9: 5294.25 | AL9: 18306 | AM9: 5040.69 | AN9: 0 | AO9: 82809.35 | AP9: 13272.48 | AQ9: 4586.76 | AR9: 2378.91 | AS9: 0 | AT9: 7472.31 | AU9: 9040.17 | AV9: 24935.27 | AW9: 43710.34
AG10: old supplies (before replacing) | AH10: 26967.32 | AI10: 31942.22 | AJ10: 96014.32 | AK10: 2385.35 | AL10: 41533.36 | AM10: 34417.95 | AN10: 90754.17 | AO10: 8932.02 | AP10: 72680.55 | AQ10: 21624.57 | AR10: 18234.06 | AS10: 54570.74 | AT10: 17420.9 | AU10: 57049.67 | AV10: 9031.19 | AW10: 41629.84 | AX10: 31597.88 | AY10: 81825.46 | AZ10: 23140.3 | BA10: 94515.33 | BB10: 28474.36 | BC10: 38689.83
B12: MAY BUDGET | I12: SW | J12: ST | K12: SP | L12: SRG | M12: WH | N12: BCM | O12: CPL | P12: MOM | Q12: MIM | R12: SR | S12: BBC | T12: BJP | U12: BMT | V12: BMC | W12: BMR | X12: BRV | Y12: BST | Z12: BGW | AA12: BHR | AB12: BJB | AC12: BLV | AD12: BRC | AE12: BSD | AF12: BCT | AG12: BMS | AH12: IRO | AI12: IAM | AJ12: IAR | AK12: IEM | AL12: ILD | AM12: IPG | AN12: IPH | AO12: ITL | AP12: RBR | AQ12: RGO | AR12: RSM | AS12: RWB | AT12: RWG | AU12: RWH | AV12: RWL | AW12: RWW | AX12: MGS | AY12: MBC | AZ12: MCG | BA12: MQG | BB12: MRG | BC12: MVF
B13: Sick Time | I13: 21021.86 | J13: 40448.18 | K13: 65337.05 | L13: 10511.57 | M13: 38810.43 | N13: 16707.57 | O13: 9379.74 | P13: 7748.66 | Q13: 18825.58 | R13: 254.44 | S13: 11310.16 | T13: 9586.65 | U13: 14113.17 | V13: 14721.61 | W13: 8606.77 | X13: 10127.77 | Y13: 12218.69 | Z13: 9765.52 | AA13: 10089.3 | AB13: 8808.86 | AC13: 15054.47 | AD13: 16466.09 | AE13: 3488.11 | AF13: 0 | AG13: 396.88 | AH13: 17526.42 | AI13: 5444.33 | AJ13: 21775.42 | AK13: 4159.02 | AL13: 10999.34 | AM13: 11199.91 | AN13: 7037.05 | AO13: 19284.59 | AP13: 18562.96 | AQ13: 19375.83 | AR13: 19815.58 | AS13: 21395.58 | AT13: 18993.64 | AU13: 19762.51 | AV13: 17364.79 | AW13: 17258.06 | AX13: 17381.56 | AY13: 10742.43 | AZ13: 18566.87 | BA13: 14524.42 | BB13: 16159.21 | BC13: 18529.23
B14: Overtime | I14: 4245.7 | J14: 2169.3 | K14: 6839.54 | L14: 3191.28 | M14: 4191.48 | N14: 31844.78 | O14: 5222.52 | P14: 7603.66 | Q14: 31531.23 | R14: 0 | S14: 3633.07 | T14: 6938.04 | U14: 1990.48 | V14: 2317.3 | W14: 2845.05 | X14: 3575.56 | Y14: 2270.6 | Z14: 67233.77 | AA14: 57108.84 | AB14: 26030.81 | AC14: 38745.96 | AD14: 49773.42 | AE14: 8191.55 | AF14: 0 | AG14: 0 | AH14: 0 | AI14: 0 | AJ14: 0 | AK14: 0 | AL14: 0 | AM14: 0 | AN14: 0 | AO14: 0 | AP14: 0 | AQ14: 0 | AR14: 0 | AS14: 0 | AT14: 0 | AU14: 0 | AV14: 0 | AW14: 0 | AX14: 0 | AY14: 0 | AZ14: 0 | BA14: 0 | BB14: 0 | BC14: 0
B15: Purchased Hours | I15: 0 | J15: 1600 | K15: 2695 | L15: 1600 | M15: 1666.63 | N15: 92379.84 | O15: 136332.82 | P15: 83029.69 | Q15: 240875.01 | R15: 510385.96 | S15: 0 | T15: 0 | U15: 0 | V15: 0 | W15: 0 | X15: 4800 | Y15: 0 | Z15: 87858.8 | AA15: 135815.16 | AB15: 188960.28 | AC15: 229853.24 | AD15: 60703.7 | AE15: 75019.82 | AF15: 792281.5 | AG15: 901623.09 | AH15: 0 | AI15: 0 | AJ15: 0 | AK15: 0 | AL15: 0 | AM15: 0 | AN15: 0 | AO15: 0 | AP15: 0 | AQ15: 0 | AR15: 0 | AS15: 0 | AT15: 0 | AU15: 0 | AV15: 0 | AW15: 0 | AX15: 0 | AY15: 0 | AZ15: 0 | BA15: 0 | BB15: 0 | BC15: 0
B16: SUPPLIES | I16: 24869.91 | J16: 33563.83 | K16: 61725.96 | L16: 3825.33 | M16: 37726.7 | N16: 19171.1 | O16: 13282.14 | P16: 8871.63 | Q16: 24761.1 | R16: 18209.52 | S16: 34578.26 | T16: 27391.97 | U16: 38576.51 | V16: 43429.81 | W16: 18769.68 | X16: 19708.08 | Y16: 30371.19 | Z16: 17085.62 | AA16: 21612.03 | AB16: 19504.32 | AC16: 26990.32 | AD16: 25936.29 | AE16: 7140.83 | AF16: 18125.34 | AG16: 25456.18 | AH16: 15314.05 | AI16: 18418.3 | AJ16: 73673.22 | AK16: 6140.88 | AL16: 24563.51 | AM16: 11525.32 | AN16: 57692.1 | AO16: 1835.48 | AP16: 61256.21 | AQ16: 9177.39 | AR16: 9716.95 | AS16: 38867.8 | AT16: 9124.32 | AU16: 36497.27 | AV16: 8326.26 | AW16: 33305.01 | AX16: 26057.68 | AY16: 104230.73 | AZ16: 18584.49 | BA16: 74337.95 | BB16: 13518.64 | BC16: 54074.53
I17: 36241.57 | J17: 20072.88 | K17: 31398.09 | L17: 73688.67 | M17: 60839.2 | N17: 0 | O17: 0 | P17: 0 | Q17: 71366.26 | R17: 8321.88 | S17: 44739.4 | T17: 24536.8 | U17: 167467.04 | V17: 63581.11 | W17: 24742.2 | X17: 33710.58 | Y17: 24973.49 | Z17: 9185.84 | AA17: 39911.61 | AB17: 26150 | AC17: 225384.81 | AD17: 56525 | AE17: 11990 | AF17: 0 | AG17: 0 | AH17: 67838.64 | AI17: 38750 | AJ17: 637.31 | AK17: 10074.73 | AL17: 14569.33 | AM17: 12109.98 | AN17: 6400 | AO17: 88348.65 | AP17: 1695 | AQ17: 22889.89 | AR17: 17461.04 | AS17: 50000 | AT17: 54221.35 | AU17: 46136.05 | AV17: 3281.7 | AW17: 52888.7
I19: SW | J19: ST | K19: SP | L19: SRG | M19: WH | N19: BCM | O19: CPL | P19: MOM | Q19: MIM | R19: SR | S19: BBC | T19: BJP | U19: BMT | V19: BMC | W19: BMR | X19: BRV | Y19: BST | Z19: BGW | AA19: BHR | AB19: BJB | AC19: BLV | AD19: BRC | AE19: BSD | AF19: BCT | AG19: BMS | AH19: IRO | AI19: IAM | AJ19: IAR | AK19: IEM | AL19: ILD | AM19: IPG | AN19: IPH | AO19: ITL | AP19: RBR | AQ19: RGO | AR19: RSM | AS19: RWB | AT19: RWG | AU19: RWH | AV19: RWL | AW19: RWW | AX19: MGS | AY19: MBC | AZ19: MCG | BA19: MQG | BB19: MRG | BC19: MVF
B20: SICK | I20: -2199.04 | J20: 86.26 | K20: 6378.01 | L20: -3445.92 | M20: -3960.22 | N20: -987.5 | O20: 5605.96 | P20: 5125.64 | Q20: 8450.01 | R20: 188.96 | S20: -12956.49 | T20: -16254.53 | U20: -1529.6 | V20: -21956.94 | W20: -5188.7 | X20: -3506.69 | Y20: -6539.31 | Z20: -18625.16 | AA20: -14591.25 | AB20: -8579.8 | AC20: -9144.13 | AD20: -17284.92 | AE20: -475.07 | AF20: -1388.24 | AG20: 307.79 | AH20: -4248.45 | AI20: -2256.94 | AJ20: -5583.52 | AK20: -10125.6 | AL20: 9059.02 | AM20: -839.11 | AN20: 1709.18 | AO20: 4626.46 | AP20: -3949.18 | AQ20: -1559.17 | AR20: 2297.74 | AS20: -9168.49 | AT20: 1582.37 | AU20: 7326.39 | AV20: 2463.67 | AW20: 1346.82 | AX20: -8884.38 | AY20: -1480.75 | AZ20: 622.04 | BA20: -5285.92 | BB20: 5092.48 | BC20: 3448.98
B21: OT | I21: -8785.88 | J21: -200.2 | K21: -15116.66 | L21: -17877.99 | M21: -5419.09 | N21: -14629.2 | O21: -3706.52 | P21: 1539.89 | Q21: 14801.56 | R21: 0 | S21: -11300.23 | T21: -1078.04 | U21: -1681.23 | V21: -8210.22 | W21: -1053.03 | X21: -16664.87 | Y21: -4910.7 | Z21: -64473.9 | AA21: -15436.26 | AB21: -10896.72 | AC21: -12086.94 | AD21: 9384.26 | AE21: -5295.82 | AF21: 0 | AG21: 0 | AH21: -80403.28 | AI21: -10432.81 | AJ21: -105165.54 | AK21: -14132.1 | AL21: -40921.82 | AM21: -27496.8 | AN21: -31843.59 | AO21: -88130.65 | AP21: -65228.87 | AQ21: -147194.64 | AR21: -88654.88 | AS21: -55308.02 | AT21: -47431.29 | AU21: -136503.59 | AV21: -77296.16 | AW21: -68396.83 | AX21: -44658.74 | AY21: -29807.78 | AZ21: -11332.16 | BA21: -30386.4 | BB21: -43046.4 | BC21: -68104.27
B22: Purchased Hours | I22: -38.18 | J22: 1407.82 | K22: -8091.3 | L22: 1561.82 | M22: 1177.07 | N22: -35933.77 | O22: -8666.29 | P22: -47568.31 | Q22: 47914.24 | R22: -18855.45 | S22: -42 | T22: -2307.9 | U22: -22144.94 | V22: -38.18 | W22: -38.18 | X22: 2400 | Y22: -375.9 | Z22: -204078.5 | AA22: -54682.03 | AB22: -144451.25 | AC22: -56543.75 | AD22: -32181.48 | AE22: -8477.99 | AF22: -84231.38 | AG22: -7165.65 | AH22: -174592.13 | AI22: -29125.87 | AJ22: -172029.02 | AK22: -1294.84 | AL22: -48674.62 | AM22: -43941.11 | AN22: -57206.25 | AO22: -147032.95 | AP22: -98347.85 | AQ22: -86371.02 | AR22: -184127.84 | AS22: -125795.41 | AT22: -237686.33 | AU22: -143621.39 | AV22: -18830.83 | AW22: -10675.57 | AX22: -279696.95 | AY22: -80309.66 | AZ22: -172370.87 | BA22: -86086.11 | BB22: -263024.39 | BC22: -156201.36
B23: Supplies | I23: -14336.22 | J23: -8709.38 | K23: -2917.12 | L23: 3043.07 | M23: -3036.04 | N23: 6388.02 | O23: 304.55 | P23: -3801.68 | Q23: 4130.5 | R23: 7623.34 | S23: 936.73 | T23: 3732.48 | U23: 8505.22 | V23: -4225.6 | W23: 1568.56 | X23: 1411.45 | Y23: 1760.26 | Z23: 2899.35 | AA23: 3625.92 | AB23: -1880.37 | AC23: 1537.58 | AD23: -924.01 | AE23: 1260.6 | AF23: -9929.65 | AG23: 54.28 | AH23: -4639.26 | AI23: 16900.77 | AJ23: 49907.23 | AK23: 483.75 | AL23: 7807.15 | AM23: -2717.26 | AN23: 51349.39 | AO23: -22546.59 | AP23: 37169.5 | AQ23: -6291.18 | AR23: -10568.67 | AS23: -16999.53 | AT23: -14255.64 | AU23: 16058.97 | AV23: -13724.83 | AW23: 14716.55 | AX23: -16925.17 | AY23: 88345.58 | AZ23: -8815.44 | BA23: 55085.01 | BB23: -1889.29 | BC23: 43028.48
I24: 18853.72 | J24: 20072.88 | K24: 9308.77 | L24: 67688.44 | M24: 2772.63 | N24: -116.63 | O24: 0 | P24: 0 | Q24: 69357.51 | R24: 8321.88 | S24: 14691.37 | T24: 9023 | U24: 140771.61 | V24: 49506.75 | W24: 18603.2 | X24: 4315.83 | Y24: 24973.49 | Z24: -45826.78 | AA24: 2112.66 | AB24: -5598.81 | AC24: 219732.79 | AD24: 4550 | AE24: 11990 | AF24: -2098.73 | AG24: -6666.24 | AH24: 16718.18 | AI24: 53892 | AJ24: -9062.05 | AK24: 4780.48 | AL24: -3736.67 | AM24: 7069.29 | AN24: 6400 | AO24: 5539.3 | AP24: -11577.48 | AQ24: 18303.13 | AR24: 15082.13 | AS24: 50000 | AT24: 46749.04 | AU24: 37095.88 | AV24: -21653.57 | AW24: 9178.36
AG27: 1% OT | AH27: 6337.7573 | AI27: 2432.9192 | AJ27: 7535.3129 | AK27: 1625.311 | AL27: 3955.1171 | AM27: 3982.8306 | AN27: 2561.7395 | AO27: 6871.4082 | AP27: 7430.4528 | AQ27: 6873.8416 | AR27: 7005.7132 | AS27: 7637.818 | AT27: 6773.2563 | AU27: 7987.8998 | AV27: 6051.3249 | AW27: 6842.548 | AX27: 6715.7963 | AY27: 3885.7758 | AZ27: 8173.9781 | BA27: 5277.1838 | BB27: 5724.5162 | BC27: 6644.121
AG28: Variance | AH28: -74065.523 | AI28: -7999.8908 | AJ28: -97630.227 | AK28: -12506.789 | AL28: -36966.703 | AM28: -23513.969 | AN28: -29281.85 | AO28: -81259.242 | AP28: -57798.417 | AQ28: -140320.8 | AR28: -81649.167 | AS28: -47670.202 | AT28: -40658.034 | AU28: -128515.69 | AV28: -71244.835 | AW28: -61554.282 | AX28: -37942.944 | AY28: -25922.004 | AZ28: -3158.1819 | BA28: -25109.216 | BB28: -37321.884 | BC28: -61460.149
C31: Site Code | D31: 45777 | E31: April Budget (as of March) | F31: YTD Totals | G31: 45778
B32: Aster | D32: 105669.35 | E32: 301928.55 | F32: 309442.95 | G32: 181292.42 | K32: 309442.95
B33: AgeCare Brandt's Creek Mews | C33: BCM | D33: 116.63 | E33: 0 | G33: -116.63 | K33: 847283.99
B34: AgeCare Cariboo Place | C34: CPL | D34: 0 | E34: 0 | G34: 0 | K34: 269956.4
B35: AgeCare Monashee Mews | C35: MOM | D35: 0 | E35: 0 | G35: 3040.3 | K35: 338692.64
B36: AgeCare Mount Ida Mews | C36: MIM | D36: 2008.75 | E36: 71366.26 | G36: 31112.31
B37: AgeCare Sun Rivers | C37: SR | D37: 0 | E37: 8321.88 | G37: 8321.88
B38: AgeCare Sagewood | C38: SW | D38: 17387.85 | E38: 36241.57 | G38: 33844.65
B39: AgeCare Seton | C39: ST | D39: 0 | E39: 20072.88 | G39: 41904.4
B40: AgeCare SkyPointe | C40: SP | D40: 22089.32 | E40: 31398.09 | G40: 15015.54
B41: AgeCare Sunrise Gardens | C41: SRG | D41: 6000.23 | E41: 73688.67 | G41: 20752.07
B42: AgeCare Walden Heights | C42: WH | D42: 58066.57 | E42: 60839.2 | G42: 27417.9
B43: Bloom | D43: 312817.74 | E43: 752897.88 | F43: 847283.99 | G43: 1158052.2
B44: AgeCare Bow Crest | C44: BBC | D44: 30048.03 | E44: 44739.4 | G44: 10809.15
B45: AgeCare Jasper Place | C45: BJP | D45: 15513.8 | E45: 24536.8 | G45: 12900
B46: AgeCare McKenzie Towne | C46: BMT | D46: 26695.43 | E46: 167467.04 | G46: 303305.14
B47: AgeCare Miller Crossing | C47: BMC | D47: 14074.36 | E47: 63581.11 | G47: 53506.75
B48: AgeCare Mount Royal | C48: BMR | D48: 6139 | E48: 24742.2 | G48: 22338.5 | K48: 105669.35 | L48: 301928.55
...

Sheet May
D2: CL | E2: GL | F2: MN | G2: OM | H2: VV | I2: HC | J2: SW | K2: ST | L2: SP | M2: SG | N2: WH | O2: BCM | P2: CPL | Q2: MOM | R2: MIM | S2: SR | T2: BBC | U2: BJP | V2: BMT | W2: BMC | X2: BMR | Y2: BRV | Z2: BST | AA2: BGW | AB2: BHR | AC2: BJB | AD2: BLV | AE2: BRC | AF2: BSD | AG2: BCT | AH2: BMS | AI2: IAM | AJ2: IAR | AK2: IEM | AL2: ILD | AM2: IPG | AN2: IPH | AO2: IRO | AP2: ITL | AQ2: RBR | AR2: RGO | AS2: RSM | AT2: RWB | AU2: RWG | AV2: RWH | AW2: RWL | AX2: RWW | AY2: MGS | AZ2: MBC | BA2: MCG | BB2: MQG | BC2: MRG | BD2: MVF
C3: Sick Time | D3: 4753.39 | E3: 51252.47 | F3: 68984.46 | G3: 3127.01 | H3: 11293.93 | I3: 1973.67 | J3: 19996.69 | K3: 46884.15 | L3: 70949.45 | M3: 10863.44 | N3: 37170.18 | O3: 12658.78 | P3: 4111.57 | Q3: 5024.14 | R3: 13474.31 | S3: 19.06 | T3: 22005.33 | U3: 19469.62 | V3: 12557.21 | W3: 27165.42 | X3: 10181.32 | Y3: 15000.2 | Z3: 17689.1 | AA3: 24336.35 | AB3: 15778.41 | AC3: 12649.58 | AD3: 39582.06 | AE3: 27320.54 | AF3: 7344.08 | AG3: 976.46 | AH3: 25.87 | AI3: 6481.26 | AJ3: 32669.34 | AK3: 12115.33 | AL3: 6236.62 | AM3: 8640.38 | AN3: 3977.41 | AO3: 21934.52 | AP3: 19559.69 | AQ3: 21096.93 | AR3: 27903.96 | AS3: 15294.09 | AT3: 37345.64 | AU3: 21163.6 | AV3: 22164.6 | AW3: 19800.31 | AX3: 18984.67 | AY3: 24458.7 | AZ3: 16562.99 | BA3: 17521.38 | BB3: 22031.18 | BC3: 15362.49 | BD3: 25883.81
C4: Overtime | D4: 764.08 | E4: 9152.24 | F4: 13026.03 | G4: 1079.57 | H4: 5308.1 | I4: 11.97 | J4: 8367.96 | K4: 3431.47 | L4: 27303.1 | M4: 11757.22 | N4: 12132.93 | O4: 43212.55 | P4: 14650.32 | Q4: 5456.53 | R4: 34874.25 | S4: 0 | T4: 32319.15 | U4: 8014.06 | V4: 4899.7 | W4: 6674.38 | X4: 4210.25 | Y4: 33441.27 | Z4: 4881.74 | AA4: 117170.52 | AB4: 86587.54 | AC4: 34723.75 | AD4: 64558.78 | AE4: 31748.12 | AF4: 12523.56 | AG4: 0 | AH4: 0 | AI4: 15490.4 | AJ4: 172931.21 | AK4: 19683.92 | AL4: 26396.91 | AM4: 28778.99 | AN4: 32192.65 | AO4: 105365.7 | AP4: 107817.43 | AQ4: 40036.21 | AR4: 156809.53 | AS4: 113484.74 | AT4: 60844.57 | AU4: 61513.54 | AV4: 145485.37 | AW4: 58199.06 | AX4: 77643.53 | AY4: 49935.67 | AZ4: 21040.74 | BA4: 14076.78 | BB4: 56221.92 | BC4: 59623.28 | BD4: 63091.55
C5: Purchased Hours | D5: 0 | E5: 34640.21 | F5: 22988 | G5: 0 | H5: -4871.46 | I5: 450009.46 | J5: 0 | K5: 816.25 | L5: 2163.2 | M5: 0 | N5: 9665.5 | O5: 75020.84 | P5: 182901.77 | Q5: 118883.16 | R5: 132128.82 | S5: 508020.42 | T5: 353.27 | U5: 0 | V5: 28299.37 | W5: 0 | X5: 0 | Y5: 0 | Z5: 0 | AA5: 140251.31 | AB5: 122349.08 | AC5: 170250.61 | AD5: 254388.66 | AE5: -23907.61 | AF5: 74459.26 | AG5: 761754.86 | AH5: 850094.45 | AI5: 42525.64 | AJ5: 181693.4 | AK5: 15613.9 | AL5: 14758.8 | AM5: 62952.36 | AN5: 41336.79 | AO5: 277293.94 | AP5: 248359.75 | AQ5: 76115.11 | AR5: 95893.71 | AS5: 201454.46 | AT5: 300157.07 | AU5: 150144.03 | AV5: 62863.42 | AW5: 37633.84 | AX5: 125153.58 | AY5: 208711.52 | AZ5: 79802.92 | BA5: 157893.04 | BB5: 85359.2 | BC5: 26073.26 | BD5: 268942.22
C6: Supplies | D6: 542.9 | E6: 44271.99 | F6: 54321.01 | G6: 1244.08 | H6: 9075.27 | I6: 15975.92 | J6: 29411.66 | K6: 33865.98 | L6: 53985.53 | M6: 2763.87 | N6: 55104.62 | O6: 14018.12 | P6: 7598.31 | Q6: 7088.72 | R6: 17555.02 | S6: 8101.57 | T6: 26779.56 | U6: 25517.95 | V6: 33981.06 | W6: 39907.33 | X6: 15823.32 | Y6: 19205.05 | Z6: 30393.2 | AA6: 36322.96 | AB6: 22654.58 | AC6: 16642.92 | AD6: 30874.95 | AE6: 35273.58 | AF6: 4085.88 | AG6: 15573.51 | AH6: 21466.57 | AI6: 10840.79 | AJ6: 13051.37 | AK6: 11233.55 | AL6: 20388.81 | AM6: 23082.37 | AN6: 5599.39 | AO6: 19489.41 | AP6: 16987.87 | AQ6: 12208.24 | AR6: 23077.64 | AS6: 10723 | AT6: 21867.53 | AU6: 27367.47 | AV6: 21801.6 | AW6: 26610.62 | AX6: 25620.21 | AY6: 6775.72 | AZ6: 5595.3 | BA6: 29220.66 | BB6: 26629.87 | BC6: 24153.94 | BD6: 19968.18
C7: CapEx | J7: 0.23299043 | K7: 0.14282416 | L7: 0.64952452 | M7: 0.056791606 | N7: 0.52289607 | O7: N/A | P7: N/A | Q7: 1.4792433 | R7: 0.36997038 | S7: N/A | T7: 0.35560193 | U7: 0.49144875 | V7: 0.19598233 | W7: 0.77062624 | X7: 0.12989222 | Y7: 0.092235566 | Z7: 0.14648557 | AA7: 0.4599947 | AB7: 0.81451148 | AC7: 2.3882986 | AD7: 0.79245019 | AE7: 0.080896622 | AF7: 0.23646502 | AG7: 0.5381359 | AH7: 1.4933947 | AI7: 0.17439662 | AJ7: 0.39247329 | AK7: 0.18230042 | AL7: 0.1456589 | AM7: 0.030531133 | AN7: 0.17505338 | AO7: 0.63366834 | AP7: 0.15879722 | AQ7: 0.099469431 | AR7: 0.51617458 | AS7: 0.36957823 | AT7: 0.11911727 | AU7: 0.081010924 | AV7: 0.1624677 | AW7: 0.42383455 | AX7: 0.062412483
C8: **Check June File to alter May for ACIL
C10: MAY BUDGET | J10: SW | K10: ST | L10: SP | M10: SG | N10: WH | O10: BCM | P10: CPL | Q10: MOM | R10: MIM | S10: SR | T10: BBC | U10: BJP | V10: BMT | W10: BMC | X10: BMR | Y10: BRV | Z10: BST | AA10: BGW | AB10: BHR | AC10: BJB | AD10: BLV | AE10: BRC | AF10: BSD | AG10: BCT | AH10: BMS | AI10: IAM | AJ10: IAR | AK10: IEM | AL10: ILD | AM10: IPG | AN10: IPH | AO10: IRO | AP10: ITL | AQ10: RBR | AR10: RGO | AS10: RSM | AT10: RWB | AU10: RWG | AV10: RWH | AW10: RWL | AX10: RWW | AY10: MGS | AZ10: MBC | BA10: MCG | BB10: MQG | BC10: MRG | BD10: MVF
C11: Sick Time | J11: 21021.86 | K11: 40448.18 | L11: 65337.05 | M11: 10511.57 | N11: 38810.43 | O11: 16707.57 | P11: 9379.74 | Q11: 7748.66 | R11: 18825.58 | S11: 254.44 | T11: 11310.16 | U11: 9586.65 | V11: 14113.17 | W11: 14721.61 | X11: 8606.77 | Y11: 10127.77 | Z11: 12218.69 | AA11: 9765.52 | AB11: 10089.3 | AC11: 8808.86 | AD11: 15054.47 | AE11: 16466.09 | AF11: 3488.11 | AG11: 0 | AH11: 396.88 | AI11: 7290.23 | AJ11: 27548.18 | AK11: 6774.33 | AL11: 13479.58 | AM11: 14337.59 | AN11: 9087.21 | AO11: 21910.61 | AP11: 24750.4 | AQ11: 22268.18 | AR11: 23288.18 | AS11: 23793.71 | AT11: 25908.84 | AU11: 22294.37 | AV11: 24091.96 | AW11: 21525.79 | AX11: 21110.22 | AY11: 22259.65 | AZ11: 13502.4 | BA11: 24276.71 | BB11: 18427.7 | BC11: 19970.14 | BD11: 22812.16
C12: Overtime | J12: 4245.7 | K12: 2169.3 | L12: 6839.54 | M12: 3191.28 | N12: 4191.48 | O12: 31844.78 | P12: 5222.52 | Q12: 7603.66 | R12: 31531.23 | S12: 0 | T12: 3633.07 | U12: 6938.04 | V12: 1990.48 | W12: 2317.3 | X12: 2845.05 | Y12: 3575.56 | Z12: 2270.6 | AA12: 67233.77 | AB12: 57108.84 | AC12: 26030.81 | AD12: 38745.96 | AE12: 49773.42 | AF12: 8191.55 | AG12: 0 | AH12: 0 | AI12: 9835.6658 | AJ12: 27464.906 | AK12: 3172.0654 | AL12: 14816.888 | AM12: 14351.577 | AN12: 9502.4376 | AO12: 22657.925 | AP12: 27535.133 | AQ12: 25206.087 | AR12: 24046.045 | AS12: 24167.875 | AT12: 27445.399 | AU12: 24000.94 | AV12: 27530.492 | AW12: 23750.974 | AX12: 23582.001 | AY12: 24319.431 | AZ12: 14625.571 | BA12: 28879.669 | BB12: 18836.091 | BC12: 19184.422 | BD12: 23865.757
C13: Purchased Hours | J13: 0 | K13: 1600 | L13: 2695 | M13: 1600 | N13: 1666.63 | O13: 92379.84 | P13: 136332.82 | Q13: 83029.69 | R13: 240875.01 | S13: 510385.96 | T13: 0 | U13: 0 | V13: 0 | W13: 0 | X13: 0 | Y13: 4800 | Z13: 0 | AA13: 87858.8 | AB13: 135815.16 | AC13: 188960.28 | AD13: 229853.24 | AE13: 60703.7 | AF13: 75019.82 | AG13: 792281.5 | AH13: 901623.09 | AI13: 7638.63 | AJ13: 34110.38 | AK13: 5558.83 | AL13: 11721.37 | AM13: 12080.11 | AN13: 7880.26 | AO13: 28238.23 | AP13: 24400.29 | AQ13: 21499 | AR13: 21546 | AS13: 20924.1 | AT13: 26061.41 | AU13: 26703.97 | AV13: 23695.14 | AW13: 22034.68 | AX13: 19403.98 | AY13: 25767.69 | AZ13: 12017.71 | BA13: 30987.45 | BB13: 16214.02 | BC13: 15881.28 | BD13: 20001.02
C14: SUPPLIES | J14: 24869.91 | K14: 33563.83 | L14: 61725.96 | M14: 3825.33 | N14: 37726.7 | O14: 19171.1 | P14: 13282.14 | Q14: 8871.63 | R14: 24761.1 | S14: 18209.52 | T14: 34578.26 | U14: 27391.97 | V14: 38576.51 | W14: 43429.81 | X14: 18769.68 | Y14: 19708.08 | Z14: 30371.19 | AA14: 17085.62 | AB14: 21612.03 | AC14: 19504.32 | AD14: 26990.32 | AE14: 25936.29 | AF14: 7140.83 | AG14: 18125.34 | AH14: 25456.18 | AI14: 3741.33 | AJ14: 6382.28 | AK14: 1303.62 | AL14: 6059.64 | AM14: 5405.13 | AN14: 5817.28 | AO14: 9421.45 | AP14: 18648.33 | AQ14: 11129.63 | AR14: 11923.27 | AS14: 6892.44 | AT14: 13066.56 | AU14: 13156.58 | AV14: 13819.79 | AW14: 9766.11 | AX14: 9646.8 | AY14: 18392.94 | AZ14: 15221.43 | BA14: 21799.04 | BB14: 14532.7 | BC14: 14532.7 | BD14: 18165.87
C17: Variance | J17: SW | K17: ST | L17: SP | M17: SG | N17: WH | O17: BCM | P17: CPL | Q17: MOM | R17: MIM | S17: SR | T17: BBC | U17: BJP | V17: BMT | W17: BMC | X17: BMR | Y17: BRV | Z17: BST | AA17: BGW | AB17: BHR | AC17: BJB | AD17: BLV | AE17: BRC | AF17: BSD | AG17: BCT | AH17: BMS | AI17: IAM | AJ17: IAR | AK17: IEM | AL17: ILD | AM17: IPG | AN17: IPH | AO17: IRO | AP17: ITL | AQ17: RBR | AR17: RGO | AS17: RSM | AT17: RWB | AU17: RWG | AV17: RWH | AW17: RWL | AX17: RWW | AY17: MGS | AZ17: MBC | BA17: MCG | BB17: MQG | BC17: MRG | BD17: MVF
C18: Sick Time | J18: 1025.17 | K18: -6435.97 | L18: -5612.4 | M18: -351.87 | N18: 1640.25 | O18: 4048.79 | P18: 5268.17 | Q18: 2724.52 | R18: 5351.27 | S18: 235.38 | T18: -10695.17 | U18: -9882.97 | V18: 1555.96 | W18: -12443.81 | X18: -1574.55 | Y18: -4872.43 | Z18: -5470.41 | AA18: -14570.83 | AB18: -5689.11 | AC18: -3840.72 | AD18: -24527.59 | AE18: -10854.45 | AF18: -3855.97 | AG18: -976.46 | AH18: 371.01 | AI18: 808.97 | AJ18: -5121.16 | AK18: -5341 | AL18: 7242.96 | AM18: 5697.21 | AN18: 5109.8 | AO18: -23.91 | AP18: 5190.71 | AQ18: 1171.25 | AR18: -4615.78 | AS18: 8499.62 | AT18: -11436.8 | AU18: 1130.77 | AV18: 1927.36 | AW18: 1725.48 | AX18: 2125.55 | AY18: -2199.05 | AZ18: -3060.59 | BA18: 6755.33 | BB18: -3603.48 | BC18: 4607.65 | BD18: -3071.65
C19: Overtime | J19: -4122.26 | K19: -1262.17 | L19: -20463.56 | M19: -8565.94 | N19: -7941.45 | O19: -11367.77 | P19: -9427.8 | Q19: 2147.13 | R19: -3343.02 | S19: 0 | T19: -28686.08 | U19: -1076.02 | V19: -2909.22 | W19: -4357.08 | X19: -1365.2 | Y19: -29865.71 | Z19: -2611.14 | AA19: -49936.75 | AB19: -29478.7 | AC19: -8692.94 | AD19: -25812.82 | AE19: 18025.3 | AF19: -4332.01 | AG19: 0 | AH19: 0 | AI19: -5654.7342 | AJ19: -145466.3 | AK19: -16511.855 | AL19: -11580.022 | AM19: -14427.413 | AN19: -22690.212 | AO19: -82707.775 | AP19: -80282.297 | AQ19: -14830.123 | AR19: -132763.49 | AS19: -89316.865 | AT19: -33399.171 | AU19: -37512.6 | AV19: -117954.88 | AW19: -34448.086 | AX19: -54061.529 | AY19: -25616.239 | AZ19: -6415.169 | BA19: 14802.889 | BB19: -37385.829 | BC19: -40438.858 | BD19: -39225.793
C20: Purchased Hours | J20: 0 | K20: 783.75 | L20: 531.8 | M20: 1600 | N20: -7998.87 | O20: 17359 | P20: -46568.95 | Q20: -35853.47 | R20: 108746.19 | S20: 2365.54 | T20: -353.27 | U20: 0 | V20: -28299.37 | W20: 0 | X20: 0 | Y20: 4800 | Z20: 0 | AA20: -52392.51 | AB20: 13466.08 | AC20: 18709.67 | AD20: -24535.42 | AE20: 84611.31 | AF20: 560.56 | AG20: 30526.64 | AH20: 51528.64 | AI20: -34887.01 | AJ20: -147583.02 | AK20: -10055.07 | AL20: -3037.43 | AM20: -50872.25 | AN20: -33456.53 | AO20: -249055.71 | AP20: -223959.46 | AQ20: -54616.11 | AR20: -74347.71 | AS20: -180530.36 | AT20: -274095.66 | AU20: -123440.06 | AV20: -39168.28 | AW20: -15599.16 | AX20: -105749.6 | AY20: -182943.83 | AZ20: -67785.21 | BA20: -126905.59 | BB20: -69145.18 | BC20: -10191.98 | BD20: -248941.2
C21: SUPPLIES | J21: -4541.75 | K21: -302.15 | L21: 7740.43 | M21: 1061.46 | N21: -17377.92 | O21: 5152.98 | P21: 5683.83 | Q21: 1782.91 | R21: 7206.08 | S21: 10107.95 | T21: 7798.7 | U21: 1874.02 | V21: 4595.45 | W21: 3522.48 | X21: 2946.36 | Y21: 503.03 | Z21: -22.01 | AA21: -19237.34 | AB21: -1042.55 | AC21: 2861.4 | AD21: -3884.63 | AE21: -9337.29 | AF21: 3054.95 | AG21: 2551.83 | AH21: 3989.61 | AI21: -7099.46 | AJ21: -6669.09 | AK21: -9929.93 | AL21: -14329.17 | AM21: -17677.24 | AN21: 217.89 | AO21: -10067.96 | AP21: 1660.46 | AQ21: -1078.61 | AR21: -11154.37 | AS21: -3830.56 | AT21: -8800.97 | AU21: -14210.89 | AV21: -7981.81 | AW21: -16844.51 | AX21: -15973.41 | AY21: 11617.22 | AZ21: 9626.13 | BA21: -7421.62 | BB21: -12097.17 | BC21: -9621.24 | BD21: -1802.31
C26: ACIL - No approved Capex Budget?
M28: ACIL | N28: 34789.97
M29: Aster | N29: 309442.95 | O29: 0.25943655
E30: 34789.97 | M30: Bloom | N30: 1081150.9 | O30: 0.30337481
C31: Aster | D31: 0.25943655 | E31: 309442.95 | M31: Iris | N31: 385043.15 | O31: 0.2276476
C32: AgeCare Sagewood | D32: 0.23299043 | M32: Regency | N32: 535223.66 | O32: 0.20734655
C33: AgeCare Seton | D33: 0.14282416
C34: AgeCare SkyPointe | D34: 0.64952452
C35: AgeCare Sunrise Gardens | D35: 0.056791606
C36: AgeCare Walden Heights | D36: 0.52289607
C37: AgeCare Brandt's Creek Mews | D37: #DIV/0!
C38: AgeCare Cariboo Place | D38: #DIV/0!
C39: AgeCare Monashee Mews | D39: 1.4792433
C40: AgeCare Mount Ida Mews | D40: 0.36997038
C41: AgeCare Sun Rivers | D41: #DIV/0!
C42: Bloom | D42: 0.30337481 | E42: 1081150.9 | I42: IAM
C43: AgeCare Bow Crest | D43: 0.35560193 | I43: IAR
C44: AgeCare Jasper Place | D44: 0.49144875 | I44: IEM
C45: AgeCare McKenzie Towne | D45: 0.19598233 | I45: ILD
C46: AgeCare Miller Crossing | D46: 0.77062624 | I46: IPG
C47: AgeCare Mount Royal | D47: 0.12989222 | I47: IPH
C48: AgeCare Riverview | D48: 0.092235566 | I48: ITL
C49: AgeCare South Terrace | D49: 0.14648557 | I49: RBR
...

Sheet June
C2: CL | D2: GL | E2: MN | F2: OM | G2: VV | H2: HC | I2: SW | J2: ST | K2: SP | L2: SG | M2: WH | N2: BCM | O2: CPL | P2: MOM | Q2: MIM | R2: SR | S2: BBC | T2: BJP | U2: BMT | V2: BMC | W2: BMR | X2: BRV | Y2: BST | Z2: BGW | AA2: BHR | AB2: BJB | AC2: BLV | AD2: BRC | AE2: BSD | AF2: BCT | AG2: BMS | AH2: IAM | AI2: IAR | AJ2: IEM | AK2: ILD | AL2: IPG | AM2: IPH | AN2: IRO | AO2: ITL | AP2: RBR | AQ2: RGO | AR2: RSM | AS2: RWB | AT2: RWG | AU2: RWH | AV2: RWL | AW2: RWW | AX2: MGS | AY2: MBC | AZ2: MCG | BA2: MQG | BB2: MRG | BC2: MVF
B3: Sick Time | C3: 1359.13 | D3: 32171.56 | E3: 51908.58 | F3: 2495.98 | G3: 6350.64 | H3: 1590.94 | I3: 31012.76 | J3: 51646.54 | K3: 69861.83 | L3: 20550.9 | M3: 52812.24 | N3: 12764.69 | O3: 4095.99 | P3: 3500.95 | Q3: 14574.34 | R3: 34.18 | S3: 9665.84 | T3: 14652.49 | U3: 18823.31 | V3: 25061.81 | W3: 12407.77 | X3: 18205.03 | Y3: 22808.22 | Z3: 18672.57 | AA3: 30696.28 | AB3: 15650.19 | AC3: 32247.47 | AD3: 26507.85 | AE3: 4276.05 | AF3: 246.39 | AG3: 46.49 | AH3: 8452.16 | AI3: 31314.46 | AJ3: 10125.21 | AK3: 8169.04 | AL3: 17744.93 | AM3: 3739.53 | AN3: 21173.81 | AO3: 25028.8 | AP3: 28829.14 | AQ3: 31965.25 | AR3: 18074.77 | AS3: 26225.6 | AT3: 17853.56 | AU3: 20390.22 | AV3: 19073.14 | AW3: 18343.37 | AX3: 38426.91 | AY3: 17349.96 | AZ3: 23144.71 | BA3: 21969.07 | BB3: 22973.88 | BC3: 15391.68
B4: Overtime | C4: 520.52 | D4: 11009.02 | E4: 19672.23 | F4: 4171.7 | G4: 7014.06 | H4: 83.02 | I4: 12512.03 | J4: 6881.75 | K4: 23953 | L4: 17369 | M4: 11005.49 | N4: 41764.6 | O4: 8755.71 | P4: 8172.55 | Q4: 36494.91 | R4: 0 | S4: 17314.11 | T4: 4984.38 | U4: 8978.45 | V4: 7775.6 | W4: 6540.83 | X4: 11016.15 | Y4: 3412.02 | Z4: 110394.55 | AA4: 39421.94 | AB4: 35738.75 | AC4: 48859.97 | AD4: 16378.14 | AE4: 10599.27 | AF4: 0 | AG4: 0 | AH4: 22321 | AI4: 123391.86 | AJ4: 13313.02 | AK4: 36147.76 | AL4: 33847.13 | AM4: 21875.21 | AN4: 111939.74 | AO4: 112872.1 | AP4: 69236.87 | AQ4: 89890.15 | AR4: 90557.51 | AS4: 23426.99 | AT4: 51403.48 | AU4: 170360.47 | AV4: 39199.69 | AW4: 55232.92 | AX4: 52915.45 | AY4: 14552.19 | AZ4: 20404.13 | BA4: 26523.49 | BB4: 35410.56 | BC4: 84915.16
B5: Purchased Hours | C5: 243.81 | D5: 8138.85 | E5: 39321.24 | F5: 0 | G5: 1474.2 | H5: 431018.39 | I5: 0 | J5: 2091.75 | K5: 15927.82 | L5: 0 | M5: 5009.9 | N5: 109224.29 | O5: 126385.19 | P5: 138659.67 | Q5: 71319.53 | R5: 498638.96 | S5: 566.28 | T5: 0 | U5: 40814.67 | V5: 0 | W5: 2513.7 | X5: 0 | Y5: 0 | Z5: 123709.23 | AA5: 147967.14 | AB5: 161814.91 | AC5: 206535.05 | AD5: 48037.9 | AE5: 62594.68 | AF5: 824487.99 | AG5: 847706.28 | AH5: 37538.31 | AI5: 115095.32 | AJ5: 21401.68 | AK5: 14473.99 | AL5: 67601.65 | AM5: 34413.8 | AN5: 224086.11 | AO5: 210698.48 | AP5: 33747.87 | AQ5: 47282.47 | AR5: 288223.02 | AS5: 231929.35 | AT5: 75490.85 | AU5: -6836.54 | AV5: 43847.38 | AW5: 85618.88 | AX5: 52664.8 | AY5: 35461.59 | AZ5: 163985.71 | BA5: 64344.2 | BB5: 46212.49 | BC5: 312764.7
B6: Supplies | C6: 820.26 | D6: 54273.99 | E6: 68047.6 | F6: 2094.15 | G6: 8756.14 | H6: 15944.48 | I6: 20800.09 | J6: 27129.2 | K6: 37960.53 | L6: 2493.47 | M6: 40968.51 | N6: 7982.37 | O6: 8469.36 | P6: 6117.92 | Q6: 13222.86 | R6: 16853.39 | S6: 19319.03 | T6: 24024.64 | U6: 35236.29 | V6: 43937.06 | W6: 13210.57 | X6: 16701.87 | Y6: 29877.2 | Z6: 7500.49 | AA6: 17294.48 | AB6: 19991.77 | AC6: 24077.75 | AD6: 25087.29 | AE6: 6585.82 | AF6: 15347.44 | AG6: 21748.59 | AH6: 9089.38 | AI6: 13783.93 | AJ6: 5801.46 | AK6: 11085.18 | AL6: 21751.7 | AM6: 12006.34 | AN6: 29016.79 | AO6: 22545.66 | AP6: 8338 | AQ6: 16445.96 | AR6: 21682.98 | AS6: -1096.02 | AT6: 17949.04 | AU6: 15519.94 | AV6: 8520.88 | AW6: 24616.8 | AX6: 23525.14 | AY6: 19111.55 | AZ6: 28690.28 | BA6: 14120.98 | BB6: 19786.53 | BC6: 23538.73
B7: CapEx | I7: 0.44590679 | J7: 0.14282416 | K7: 0.82848578 | L7: 0.057559975 | M7: 0.65947319 | N7: N/A | O7: N/A | P7: 7.28083 | Q7: 0.56442231 | R7: N/A | S7: 0.42497005 | T7: 0.59256016 | U7: 0.2270588 | V7: 1.0286225 | W7: 0.53474052 | X7: 0.092235566 | Y7: 0.39012277 | Z7: 0.56551711 | AA7: 0.81451104 | AB7: 2.8940029 | AC7: 1.3417149 | AD7: 0.094220401 | AE7: 0.23646522 | AF7: 2.3662128 | AG7: 1.4933947 | AH7: 0.18 | AI7: 0.43 | AJ7: 0.2 | AK7: 0.15 | AL7: 0.22 | AM7: 0.03 | AN7: 1.24 | AO7: 0.18 | AP7: 0.3 | AQ7: 0.58 | AR7: 0.46 | AS7: 0.12 | AT7: 0.47 | AU7: 0.16 | AV7: 0.51 | AW7: 0.12
B10: MAY BUDGET | I10: SW | J10: ST | K10: SP | L10: SG | M10: WH | N10: BCM | O10: CPL | P10: MOM | Q10: MIM | R10: SR | S10: BBC | T10: BJP | U10: BMT | V10: BMC | W10: BMR | X10: BRV | Y10: BST | Z10: BGW | AA10: BHR | AB10: BJB | AC10: BLV | AD10: BRC | AE10: BSD | AF10: BCT | AG10: BMS | AH10: IAM | AI10: IAR | AJ10: IEM | AK10: ILD | AL10: IPG | AM10: IPH | AN10: IRO | AO10: ITL | AP10: RBR | AQ10: RGO | AR10: RSM | AS10: RWB | AT10: RWG | AU10: RWH | AV10: RWL | AW10: RWW | AX10: MGS | AY10: MBC | AZ10: MCG | BA10: MQG | BB10: MRG | BC10: MVF
B11: Sick Time | I11: 20154.7 | J11: 38639.96 | K11: 62643.75 | L11: 10040.76 | M11: 37145.29 | N11: 15772.04 | O11: 8382.57 | P11: 7326.67 | Q11: 17777.22 | R11: 245.7 | S11: 10785.77 | T11: 9200.51 | U11: 13572.51 | V11: 14112.79 | W11: 8252.18 | X11: 9621.52 | Y11: 11652.48 | Z11: 9170.66 | AA11: 9594.55 | AB11: 8443.24 | AC11: 14286.51 | AD11: 15670.26 | AE11: 3318.66 | AF11: 0 | AG11: 380.68 | AH11: 6922.61 | AI11: 26272.99 | AJ11: 6429.67 | AK11: 12832.53 | AL11: 13678.01 | AM11: 8650.93 | AN11: 20903.63 | AO11: 23556.27 | AP11: 21212.98 | AQ11: 22174.03 | AR11: 22611.43 | AS11: 24599.24 | AT11: 21234.78 | AU11: 22916.47 | AV11: 20510.29 | AW11: 20029.69 | AX11: 21461.58 | AY11: 12698.02 | AZ11: 23402.66 | BA11: 17522.97 | BB11: 19032.41 | BC11: 21725.35
B12: Overtime | I12: 4111.26 | J12: 2099.33 | K12: 6618.92 | L12: 3088.34 | M12: 4056.28 | N12: 30817.52 | O12: 5140.84 | P12: 7358.38 | Q12: 30606.89 | R12: 0 | S12: 3633.07 | T12: 6938.04 | U12: 1990.48 | V12: 2317.3 | W12: 2845.05 | X12: 3575.56 | Y12: 2270.6 | Z12: 67233.77 | AA12: 57108.84 | AB12: 26030.81 | AC12: 38745.96 | AD12: 49773.42 | AE12: 8191.55 | AF12: 0 | AG12: 0 | AH12: 4793.3408 | AI12: 14861.411 | AJ12: 3184.0724 | AK12: 7789.544 | AL12: 7858.3502 | AM12: 5050.9774 | AN12: 12507.972 | AO12: 13529.497 | AP12: 14636.328 | AQ12: 13535.558 | AR12: 13773.949 | AS12: 15000.542 | AT12: 13084.468 | AU12: 15702.852 | AV12: 11912.663 | AW12: 13431.734 | AX12: 13405.069 | AY12: 7573.5798 | AZ12: 16302.558 | BA12: 10387.064 | BB12: 11287.876 | BC12: 13083.147
B13: Purchased Hours | I13: 0 | J13: 1600 | K13: 2695 | L13: 1600 | M13: 1666.63 | N13: 89497.8 | O13: 148766.22 | P13: 80584.64 | Q13: 236380.34 | R13: 496644.86 | S13: 0 | T13: 0 | U13: 0 | V13: 0 | W13: 0 | X13: 4800 | Y13: 0 | Z13: 87858.8 | AA13: 135815.16 | AB13: 188960.28 | AC13: 229853.24 | AD13: 60703.7 | AE13: 75019.82 | AF13: 792281.5 | AG13: 901623.09 | AH13: 7638.63 | AI13: 34110.38 | AJ13: 5558.83 | AK13: 11721.37 | AL13: 12080.11 | AM13: 7880.26 | AN13: 28238.23 | AO13: 24400.29 | AP13: 21499 | AQ13: 21546 | AR13: 20924.1 | AS13: 26061.41 | AT13: 26703.97 | AU13: 23695.14 | AV13: 22034.68 | AW13: 19403.98 | AX13: 25522.69 | AY13: 12017.71 | AZ13: 30987.45 | BA13: 16214.02 | BB13: 15881.28 | BC13: 20001.02
B14: SUPPLIES | I14: 24067.67 | J14: 32481.13 | K14: 59734.81 | L14: 3701.95 | M14: 36509.7 | N14: 18552.68 | O14: 12853.7 | P14: 8585.46 | Q14: 23962.36 | R14: 17622.12 | S14: 34578.26 | T14: 27391.97 | U14: 38576.51 | V14: 43429.81 | W14: 18769.68 | X14: 19708.08 | Y14: 30371.19 | Z14: 17085.62 | AA14: 21612.03 | AB14: 19504.32 | AC14: 26990.32 | AD14: 25936.29 | AE14: 7140.83 | AF14: 18125.34 | AG14: 25456.18 | AH14: 3620.65 | AI14: 6176.4 | AJ14: 1261.57 | AK14: 5864.17 | AL14: 5230.77 | AM14: 5629.63 | AN14: 9117.53 | AO14: 18046.77 | AP14: 10770.61 | AQ14: 11538.65 | AR14: 6670.11 | AS14: 12645.06 | AT14: 12732.18 | AU14: 13373.99 | AV14: 9451.08 | AW14: 9335.61 | AX14: 17799.62 | AY14: 14730.42 | AZ14: 21095.85 | BA14: 14063.9 | BB14: 14063.9 | BC14: 17579.87
B17: Variance | I17: SW | J17: ST | K17: SP | L17: SG | M17: WH | N17: BCM | O17: CPL | P17: MOM | Q17: MIM | R17: SR | S17: BBC | T17: BJP | U17: BMT | V17: BMC | W17: BMR | X17: BRV | Y17: BST | Z17: BGW | AA17: BHR | AB17: BJB | AC17: BLV | AD17: BRC | AE17: BSD | AF17: BCT | AG17: BMS | AH17: IAM | AI17: IAR | AJ17: IEM | AK17: ILD | AL17: IPG | AM17: IPH | AN17: IRO | AO17: ITL | AP17: RBR | AQ17: RGO | AR17: RSM | AS17: RWB | AT17: RWG | AU17: RWH | AV17: RWL | AW17: RWW | AX17: MGS | AY17: MBC | AZ17: MCG | BA17: MQG | BB17: MRG | BC17: MVF
B18: Sick Time | I18: -10858.06 | J18: -13006.58 | K18: -7218.08 | L18: -10510.14 | M18: -15666.95 | N18: 3007.35 | O18: 4286.58 | P18: 3825.72 | Q18: 3202.88 | R18: 211.52 | S18: 1119.93 | T18: -5451.98 | U18: -5250.8 | V18: -10949.02 | W18: -4155.59 | X18: -8583.51 | Y18: -11155.74 | Z18: -9501.91 | AA18: -21101.73 | AB18: -7206.95 | AC18: -17960.96 | AD18: -10837.59 | AE18: -957.39 | AF18: -246.39 | AG18: 334.19 | AH18: -1529.55 | AI18: -5041.47 | AJ18: -3695.54 | AK18: 4663.49 | AL18: -4066.92 | AM18: 4911.4 | AN18: -270.18 | AO18: -1472.53 | AP18: -7616.16 | AQ18: -9791.22 | AR18: 4536.66 | AS18: -1626.36 | AT18: 3381.22 | AU18: 2526.25 | AV18: 1437.15 | AW18: 1686.32 | AX18: -16965.33 | AY18: -4651.94 | AZ18: 257.95 | BA18: -4446.1 | BB18: -3941.47 | BC18: 6333.67
B19: Overtime | I19: -8400.77 | J19: -4782.42 | K19: -17334.08 | L19: -14280.66 | M19: -6949.21 | N19: -10947.08 | O19: -3614.87 | P19: -814.17 | Q19: -5888.02 | R19: 0 | S19: -13681.04 | T19: 1953.66 | U19: -6987.97 | V19: -5458.3 | W19: -3695.78 | X19: -7440.59 | Y19: -1141.42 | Z19: -43160.78 | AA19: 17686.9 | AB19: -9707.94 | AC19: -10114.01 | AD19: 33395.28 | AE19: -2407.72 | AF19: 0 | AG19: 0 | AH19: -17527.659 | AI19: -108530.45 | AJ19: -10128.948 | AK19: -28358.216 | AL19: -25988.78 | AM19: -16824.233 | AN19: -99431.768 | AO19: -99342.603 | AP19: -54600.542 | AQ19: -76354.592 | AR19: -76783.561 | AS19: -8426.4482 | AT19: -38319.012 | AU19: -154657.62 | AV19: -27287.027 | AW19: -41801.186 | AX19: -39510.381 | AY19: -6978.6102 | AZ19: -4101.5718 | BA19: -16136.426 | BB19: -24122.684 | BC19: -71832.013
B20: Purchased Hours | I20: 0 | J20: -491.75 | K20: -13232.82 | L20: 1600 | M20: -3343.27 | N20: -19726.49 | O20: 22381.03 | P20: -58075.03 | Q20: 165060.81 | R20: -1994.1 | S20: -566.28 | T20: 0 | U20: -40814.67 | V20: 0 | W20: -2513.7 | X20: 4800 | Y20: 0 | Z20: -35850.43 | AA20: -12151.98 | AB20: 27145.37 | AC20: 23318.19 | AD20: 12665.8 | AE20: 12425.14 | AF20: -32206.49 | AG20: 53916.81 | AH20: -29899.68 | AI20: -80984.94 | AJ20: -15842.85 | AK20: -2752.62 | AL20: -55521.54 | AM20: -26533.54 | AN20: -195847.88 | AO20: -186298.19 | AP20: -12248.87 | AQ20: -25736.47 | AR20: -267298.92 | AS20: -205867.94 | AT20: -48786.88 | AU20: 30531.68 | AV20: -21812.7 | AW20: -66214.9 | AX20: -27142.11 | AY20: -23443.88 | AZ20: -132998.26 | BA20: -48130.18 | BB20: -30331.21 | BC20: -292763.68
B21: SUPPLIES | I21: 3267.58 | J21: 5351.93 | K21: 21774.28 | L21: 1208.48 | M21: -4458.81 | N21: 10570.31 | O21: 4384.34 | P21: 2467.54 | Q21: 10739.5 | R21: 768.73 | S21: 15259.23 | T21: 3367.33 | U21: 3340.22 | V21: -507.25 | W21: 5559.11 | X21: 3006.21 | Y21: 493.99 | Z21: 9585.13 | AA21: 4317.55 | AB21: -487.45 | AC21: 2912.57 | AD21: 849 | AE21: 555.01 | AF21: 2777.9 | AG21: 3707.59 | AH21: -5468.73 | AI21: -7607.53 | AJ21: -4539.89 | AK21: -5221.01 | AL21: -16520.93 | AM21: -6376.71 | AN21: -19899.26 | AO21: -4498.89 | AP21: 2432.61 | AQ21: -4907.31 | AR21: -15012.87 | AS21: 13741.08 | AT21: -5216.86 | AU21: -2145.95 | AV21: 930.2 | AW21: -15281.19 | AX21: -5725.52 | AY21: -4381.13 | AZ21: -7594.43 | BA21: -57.08 | BB21: -5722.63 | BC21: -5958.86
B29: Aster | D29: 0.35770254
B30: AgeCare Brandt's Creek Mews | C30: BCM | D30: #DIV/0!
B31: AgeCare Cariboo Place | C31: CPL | D31: #DIV/0!
B32: AgeCare Monashee Mews | C32: MOM | D32: 7.28083
B33: AgeCare Mount Ida Mews | C33: MIM | D33: 0.56442231
B34: AgeCare Sun Rivers | C34: SR | D34: #DIV/0!
B35: AgeCare Sagewood | C35: SW | D35: 0.44590679
B36: AgeCare Seton | C36: ST | D36: 0.14282416
B37: AgeCare SkyPointe | C37: SP | D37: 0.82848578
B38: AgeCare Sunrise Gardens | C38: SG | D38: 0.057559975
B39: AgeCare Walden Heights | C39: WH | D39: 0.65947319
B40: Bloom | D40: 0.3988867
B41: AgeCare Bow Crest | D41: 0.42497005
B42: AgeCare Jasper Place | D42: 0.59256016
B43: AgeCare McKenzie Towne | D43: 0.2270588
B44: AgeCare Miller Crossing | D44: 1.0286225
B45: AgeCare Mount Royal | D45: 0.53474052
B46: AgeCare Riverview | D46: 0.092235566
B47: AgeCare South Terrace | D47: 0.39012277
B48: AgeCare Carlton | D48: 2.3662128
B49: AgeCare Glenwarren | D49: 0.56551711
B50: AgeCare Holyrood | D50: 0.81451104
B51: AgeCare James Bay | D51: 2.8940029
... B73: West Williams (RWW) | D73: 0.12

Sheet July
C2: CL | D2: GL | E2: MN | F2: OM | G2: VV | H2: HC | I2: SW | J2: ST | K2: SP | L2: SG | M2: WH | N2: BCM | O2: CPL | P2: MOM | Q2: MIM | R2: SR | S2: BBC | T2: BJP | U2: BMT | V2: BMC | W2: BMR | X2: BRV | Y2: BST | Z2: BGW | AA2: BHR | AB2: BJB | AC2: BLV | AD2: BRC | AE2: BSD | AF2: BCT | AG2: BMS | AH2: IAM | AI2: IAR | AJ2: IEM | AK2: ILD | AL2: IPG | AM2: IPH | AN2: IRO | AO2: ITL | AP2: RBR | AQ2: RGO | AR2: RSM | AS2: RWB | AT2: RWG | AU2: RWH | AV2: RWL | AW2: RWW | AX2: MGS | AY2: MBC | AZ2: MCG | BA2: MQG | BB2: MRG | BC2: MVF
B3: Sick Time | C3: 3470.42 | D3: 33359.5 | E3: 33959 | F3: -447.2 | G3: 6586.75 | H3: 1904.15 | I3: 24726.65 | J3: 50862.93 | K3: 74734.32 | L3: 10507.17 | M3: 43595.25 | N3: 10301.2 | O3: 4607.7 | P3: 4331.33 | Q3: 12606.96 | R3: 897.33 | S3: 15263.89 | T3: 14195.8 | U3: 11643.51 | V3: 26299.68 | W3: 18652.67 | X3: 17465.74 | Y3: 19928.6 | Z3: 18215.93 | AA3: 25695.26 | AB3: 10238.06 | AC3: 37793.87 | AD3: 30400.25 | AE3: 1910.88 | AF3: 440.45 | AG3: 231.13 | AH3: 11174.49 | AI3: 25159.64 | AJ3: 1731.26 | AK3: 5560.12 | AL3: 16155.5 | AM3: 6598.46 | AN3: 17483.12 | AO3: 22724.48 | AP3: 18278.29 | AQ3: 27808.98 | AR3: 19153.68 | AS3: 27564.41 | AT3: 15575.67 | AU3: 12838.05 | AV3: 13658.03 | AW3: 18871.14 | AX3: 24426.33 | AY3: 13170.13 | AZ3: 20855.87 | BA3: 23586.07 | BB3: 18005.93 | BC3: 14739.62
B4: Overtime | C4: 1140.73 | D4: 5353.18 | E4: 37485.24 | F4: 3041.28 | G4: 9925.88 | H4: 296.81 | I4: 4560.44 | J4: 8541.48 | K4: 27912.32 | L4: 8555.93 | M4: 11789.88 | N4: 43476.95 | O4: 8508.02 | P4: 8150.31 | Q4: 46695.42 | R4: 0 | S4: 24623.86 | T4: 4541.26 | U4: 3821.42 | V4: 6837.76 | W4: 8425.91 | X4: 15497.82 | Y4: 8353.16 | Z4: 86924.01 | AA4: 34067.43 | AB4: 33705.68 | AC4: 55633.72 | AD4: 26380.56 | AE4: 10168.14 | AF4: 0 | AG4: 0 | AH4: 35863.58 | AI4: 98922.93 | AJ4: 19366.43 | AK4: 43050.54 | AL4: 39573.52 | AM4: 23210.75 | AN4: 112294.24 | AO4: 104030.28 | AP4: 71090.39 | AQ4: 122981.18 | AR4: 126989.03 | AS4: 39066.85 | AT4: 38410.34 | AU4: 166347.63 | AV4: 58330.26 | AW4: 74381.55 | AX4: 39052.74 | AY4: 18660.11 | AZ4: 21412.29 | BA4: 36375.99 | BB4: 51907.79 | BC4: 103599.96
B5: Purchased Hours | C5: 0 | D5: 23093.44 | E5: 41972 | F5: 0 | G5: 4504.4 | H5: 442565.65 | I5: 0 | J5: 3783.56 | K5: 18970.88 | L5: 0 | M5: 20113.46 | N5: 31010.15 | O5: 132645.81 | P5: 112589.83 | Q5: 78748.73 | R5: 497765.6 | S5: 672.84 | T5: 0 | U5: 22188.71 | V5: 0 | W5: 114.98 | X5: 715 | Y5: 278.25 | Z5: 127928.3 | AA5: 132784.84 | AB5: 221176.65 | AC5: 225464.05 | AD5: 47398.01 | AE5: 76777.49 | AF5: 802547.66 | AG5: 875239.15 | AH5: 64546.23 | AI5: 112956.97 | AJ5: 11064.71 | AK5: 18338.81 | AL5: 118651.62 | AM5: 30084.26 | AN5: 252871.71 | AO5: 266389.59 | AP5: 75724.66 | AQ5: 59395.59 | AR5: 306056.26 | AS5: 40848.16 | AT5: 59350.69 | AU5: 73619.42 | AV5: 36927.57 | AW5: 59201.68 | AX5: 279278.28 | AY5: 63276.36 | AZ5: 108094.76 | BA5: 171422.25 | BB5: 10483.6 | BC5: 114917.68
B6: Supplies | C6: 968.13 | D6: 54809.75 | E6: 51309.2 | F6: 1761.5 | G6: 7881.41 | H6: 18231.94 | I6: 34794.72 | J6: 42961.54 | K6: 82413.3 | L6: 6090.45 | M6: 47639.51 | N6: 15419.58 | O6: 3090.13 | P6: 4434.18 | Q6: 5216.63 | R6: 17087.75 | S6: 30036.28 | T6: 24602.74 | U6: 32268.92 | V6: 47102.04 | W6: 9791.37 | X6: 20251.37 | Y6: 30074.31 | Z6: 13624.22 | AA6: 20061.29 | AB6: 22545.6 | AC6: 23141.01 | AD6: 35705.24 | AE6: 5704.98 | AF6: 15866.64 | AG6: 47166.98 | AH6: 13191.36 | AI6: 1391.09 | AJ6: 5613.93 | AK6: 10033.72 | AL6: 18204.84 | AM6: 6167.05 | AN6: -1361.57 | AO6: 15547.37 | AP6: 18201.51 | AQ6: 24947.68 | AR6: 35719.23 | AS6: 17654.53 | AT6: 18949.41 | AU6: 18657.78 | AV6: 16917.12 | AW6: 18202.42 | AX6: 18962.7 | AY6: -5698.87 | AZ6: 19429.17 | BA6: 14109.46 | BB6: 19909.91 | BC6: 15273.17
B7: CapEx | I7: 0.49822569 | J7: 0.16059526 | K7: 0.92954167 | L7: 0.2634442 | M7: 0.67234428 | N7: NA | O7: NA | P7: 8.4694333 | Q7: 0.56442231 | R7: NA | S7: 0.47548631 | T7: 0.59256016 | U7: 0.25992045 | V7: 1.1098011 | W7: 0.50505988 | X7: 0.12775564 | Y7: 0.41765967 | Z7: 0.63206256 | AA7: 1.3493816 | AB7: 3.0327173 | AC7: 1.5745838 | AD7: 0.30861358 | AE7: 0.31839133 | AF7: 0.5381359 | AG7: 1.4933947 | AH7: 0.56460942 | AI7: 0.48381935 | AJ7: 0.24874058 | AK7: 0.14542792 | AL7: 0.25177231 | AM7: 1.2530035 | AN7: 0.19776771 | AO7: 0.18550085 | AP7: 0.35496405 | AQ7: 0.66974491 | AR7: 0.46312891 | AS7: 0.3204278 | AT7: 0.47464121 | AU7: 0.16596715 | AV7: 0.78033857 | AW7: 0.18865872
B10: July Budget | C10: CL | D10: GL | E10: MN | F10: OM | G10: VV | H10: HC | I10: SW | J10: ST | K10: SP | L10: SG | M10: WH | N10: BCM | O10: CPL | P10: MOM | Q10: MIM | R10: SR | S10: BBC | T10: BJP | U10: BMT | V10: BMC | W10: BMR | X10: BRV | Y10: BST | Z10: BGW | AA10: BHR | AB10: BJB | AC10: BLV | AD10: BRC | AE10: BSD | AF10: BCT | AG10: BMS | AH10: IAM | AI10: IAR | AJ10: IEM | AK10: ILD | AL10: IPG | AM10: IPH | AN10: IRO | AO10: ITL | AP10: RBR | AQ10: RGO | AR10: RSM | AS10: RWB | AT10: RWG | AU10: RWH | AV10: RWL | AW10: RWW | AX10: MGS | AY10: MBC | AZ10: MCG | BA10: MQG | BB10: MRG | BC10: MVF
B11: Sick Time | I11: 21021.86 | J11: 40448.18 | K11: 65337.05 | L11: 10511.57 | M11: 38810.43 | N11: 16707.57 | O11: 8870.3 | P11: 7748.66 | Q11: 18825.58 | R11: 254.44 | S11: 11310.16 | T11: 9586.65 | U11: 14113.17 | V11: 14721.61 | W11: 8606.77 | X11: 10127.77 | Y11: 12218.69 | Z11: 9765.52 | AA11: 10089.3 | AB11: 8808.86 | AC11: 15054.47 | AD11: 16466.09 | AE11: 3488.11 | AF11: 0 | AG11: 396.88 | AH11: 7290.23 | AI11: 27548.18 | AJ11: 6783.21 | AK11: 13479.58 | AL11: 14337.59 | AM11: 9087.21 | AN11: 21910.61 | AO11: 24750.4 | AP11: 22268.18 | AQ11: 23288.18 | AR11: 23827.8 | AS11: 25908.84 | AT11: 22294.37 | AU11: 24130.68 | AV11: 21528.55 | AW11: 21110.22 | AX11: 22262.95 | AY11: 13502.4 | AZ11: 24276.71 | BA11: 18430.26 | BB11: 19970.57 | BC11: 22814.47
B12: Overtime | I12: 4247.26 | J12: 2169.3 | K12: 6839.54 | L12: 3191.28 | M12: 4191.48 | N12: 31844.78 | O12: 5222.52 | P12: 7603.66 | Q12: 31531.23 | R12: 0 | S12: 3633.07 | T12: 6938.04 | U12: 1990.48 | V12: 2317.3 | W12: 2845.05 | X12: 3575.56 | Y12: 2270.6 | Z12: 67233.77 | AA12: 57108.84 | AB12: 26030.81 | AC12: 38745.96 | AD12: 49773.42 | AE12: 8191.55 | AF12: 0 | AG12: 0 | AH12: 10047.987 | AI12: 31147.372 | AJ12: 6707.9968 | AK12: 16328.016 | AL12: 16447.193 | AM12: 10583.716 | AN12: 26184.293 | AO12: 28394.222 | AP12: 30701.391 | AQ12: 28398.465 | AR12: 28942.688 | AS12: 31583.086 | AT12: 27455.306 | AU12: 33014.948 | AV12: 25003.976 | AW12: 28260.552 | AX12: 27750.24 | AY12: 16030.934 | AZ12: 33765.932 | BA12: 21800.972 | BB12: 23638.196 | BC12: 27444.615
B13: Purchased Hours | I13: 0 | J13: 1600 | K13: 2695 | L13: 1600 | M13: 1666.63 | N13: 92379.84 | O13: 151244.54 | P13: 83549.69 | Q13: 240875.01 | R13: 510385.96 | S13: 0 | T13: 0 | U13: 0 | V13: 0 | W13: 0 | X13: 4800 | Y13: 0 | Z13: 87858.8 | AA13: 135815.16 | AB13: 188960.28 | AC13: 225853.24 | AD13: 60703.7 | AE13: 75019.82 | AF13: 792281.5 | AG13: 901623.09 | AH13: 7638.63 | AI13: 34110.38 | AJ13: 5558.83 | AK13: 11721.37 | AL13: 12080.11 | AM13: 7880.26 | AN13: 28238.23 | AO13: 24400.29 | AP13: 21499 | AQ13: 21546 | AR13: 20924.1 | AS13: 26061.41 | AT13: 26703.97 | AU13: 23695.14 | AV13: 22034.68 | AW13: 19403.98 | AX13: 25767.69 | AY13: 12017.71 | AZ13: 30987.45 | BA13: 16214.02 | BB13: 15881.28 | BC13: 20001.02
B14: SUPPLIES | I14: 24869.91 | J14: 33563.83 | K14: 61725.96 | L14: 3825.33 | M14: 37726.7 | N14: 19171.1 | O14: 13282.14 | P14: 8871.63 | Q14: 24761.1 | R14: 18209.52 | S14: 34578.26 | T14: 27391.97 | U14: 38576.51 | V14: 43429.81 | W14: 18769.68 | X14: 19708.08 | Y14: 30371.19 | Z14: 17085.62 | AA14: 21612.03 | AB14: 19504.32 | AC14: 26990.32 | AD14: 25936.29 | AE14: 7140.83 | AF14: 18125.34 | AG14: 25456.18 | AH14: 3741.33 | AI14: 6382.28 | AJ14: 1303.62 | AK14: 6059.64 | AL14: 5405.13 | AM14: 5817.28 | AN14: 9421.45 | AO14: 18648.33 | AP14: 11129.63 | AQ14: 11923.27 | AR14: 6892.44 | AS14: 13066.56 | AT14: 13156.58 | AU14: 13819.79 | AV14: 9766.11 | AW14: 9646.8 | AX14: 18392.94 | AY14: 15221.43 | AZ14: 21799.04 | BA14: 14532.7 | BB14: 14532.7 | BC14: 18165.87
B17: Variance | C17: CL | D17: GL | E17: MN | F17: OM | G17: VV | H17: HC | I17: SW | J17: ST | K17: SP | L17: SG | M17: WH | N17: BCM | O17: CPL | P17: MOM | Q17: MIM | R17: SR | S17: BBC | T17: BJP | U17: BMT | V17: BMC | W17: BMR | X17: BRV | Y17: BST | Z17: BGW | AA17: BHR | AB17: BJB | AC17: BLV | AD17: BRC | AE17: BSD | AF17: BCT | AG17: BMS | AH17: IAM | AI17: IAR | AJ17: IEM | AK17: ILD | AL17: IPG | AM17: IPH | AN17: IRO | AO17: ITL | AP17: RBR | AQ17: RGO | AR17: RSM | AS17: RWB | AT17: RWG | AU17: RWH | AV17: RWL | AW17: RWW | AX17: MGS | AY17: MBC | AZ17: MCG | BA17: MQG | BB17: MRG | BC17: MVF
B18: Sick Time | I18: -3704.79 | J18: -10414.75 | K18: -9397.27 | L18: 4.4 | M18: -4784.82 | N18: 6406.37 | O18: 4262.6 | P18: 3417.33 | Q18: 6218.62 | R18: -642.89 | S18: -3953.73 | T18: -4609.15 | U18: 2469.66 | V18: -11578.07 | W18: -10045.9 | X18: -7337.97 | Y18: -7709.91 | Z18: -8450.41 | AA18: -15605.96 | AB18: -1429.2 | AC18: -22739.4 | AD18: -13934.16 | AE18: 1577.23 | AF18: -440.45 | AG18: 165.75 | AH18: -3884.26 | AI18: 2388.54 | AJ18: 5051.95 | AK18: 7919.46 | AL18: -1817.91 | AM18: 2488.75 | AN18: 4427.49 | AO18: 2025.92 | AP18: 3989.89 | AQ18: -4520.8 | AR18: 4674.12 | AS18: -1655.57 | AT18: 6718.7 | AU18: 11292.63 | AV18: 7870.52 | AW18: 2239.08 | AX18: -2163.38 | AY18: 332.27 | AZ18: 3420.84 | BA18: -5155.81 | BB18: 1964.64 | BC18: 8074.85
B19: Overtime | I19: -313.18 | J19: -6372.18 | K19: -21072.78 | L19: -5364.65 | M19: -7598.4 | N19: -11632.17 | O19: -3285.5 | P19: -546.65 | Q19: -15164.19 | R19: 0 | S19: -20990.79 | T19: 2396.78 | U19: -1830.94 | V19: -4520.46 | W19: -5580.86 | X19: -11922.26 | Y19: -6082.56 | Z19: -19690.24 | AA19: 23041.41 | AB19: -7674.87 | AC19: -16887.76 | AD19: 23392.86 | AE19: -1976.59 | AF19: 0 | AG19: 0 | AH19: -25815.593 | AI19: -67775.558 | AJ19: -12658.433 | AK19: -26722.524 | AL19: -23126.327 | AM19: -12627.034 | AN19: -86109.947 | AO19: -75636.058 | AP19: -40388.999 | AQ19: -94582.715 | AR19: -98046.342 | AS19: -7483.7644 | AT19: -10955.034 | AU19: -133332.68 | AV19: -33326.284 | AW19: -46120.998 | AX19: -11302.5 | AY19: -2629.176 | AZ19: 12353.642 | BA19: -14575.018 | BB19: -28269.594 | BC19: -76155.345
B20: Purchased Hours | I20: 0 | J20: -2183.56 | K20: -16275.88 | L20: 1600 | M20: -18446.83 | N20: 61369.69 | O20: 18598.73 | P20: -29040.14 | Q20: 162126.28 | R20: 12620.36 | S20: -672.84 | T20: 0 | U20: -22188.71 | V20: 0 | W20: -114.98 | X20: 4085 | Y20: -278.25 | Z20: -40069.5 | AA20: 3030.32 | AB20: -32216.37 | AC20: 389.19 | AD20: 13305.69 | AE20: -1757.67 | AF20: -10266.16 | AG20: 26383.94 | AH20: -56907.6 | AI20: -78846.59 | AJ20: -5505.88 | AK20: -6617.44 | AL20: -106571.51 | AM20: -22204 | AN20: -224633.48 | AO20: -241989.3 | AP20: -54225.66 | AQ20: -37849.59 | AR20: -285132.16 | AS20: -14786.75 | AT20: -32646.72 | AU20: -49924.28 | AV20: -14892.89 | AW20: -39797.7 | AX20: -253510.59 | AY20: -51258.65 | AZ20: -77107.31 | BA20: -155208.23 | BB20: 5397.68 | BC20: -94916.66
B21: SUPPLIES | I21: -9924.81 | J21: -9397.71 | K21: -20687.34 | L21: -2265.12 | M21: -9912.81 | N21: 3751.52 | O21: 10192.01 | P21: 4437.45 | Q21: 19544.47 | R21: 1121.77 | S21: 4541.98 | T21: 2789.23 | U21: 6307.59 | V21: -3672.23 | W21: 8978.31 | X21: -543.29 | Y21: 296.88 | Z21: 3461.4 | AA21: 1550.74 | AB21: -3041.28 | AC21: 3849.31 | AD21: -9768.95 | AE21: 1435.85 | AF21: 2258.7 | AG21: -21710.8 | AH21: -9450.03 | AI21: 4991.19 | AJ21: -4310.31 | AK21: -3974.08 | AL21: -12799.71 | AM21: -349.77 | AN21: 10783.02 | AO21: 3100.96 | AP21: -7071.88 | AQ21: -13024.41 | AR21: -28826.79 | AS21: -4587.97 | AT21: -5792.83 | AU21: -4837.99 | AV21: -7151.01 | AW21: -8555.62 | AX21: -569.76 | AY21: 20920.3 | AZ21: 2369.87 | BA21: 423.24 | BB21: -5377.21 | BC21: 2892.7
AH25: -2722.33 | AI25: 6154.82 | AJ25: 8393.95 | AK25: 2608.92 | AL25: 1589.43 | AM25: -2858.93 | AN25: 3690.69 | AO25: 2304.32 | AP25: 10550.85 | AQ25: 4156.27 | AR25: -1078.91 | AS25: -1338.81 | AT25: 2277.89 | AU25: 7552.17 | AV25: 5415.11 | AW25: -527.77 | AX25: 14000.58 | AY25: 4179.83 | AZ25: 2288.84 | BA25: -1617 | BB25: 4967.95 | BC25: 652.06
AH26: -13542.58 | AI26: 24468.93 | AJ26: -6053.41 | AK26: -6902.78 | AL26: -5726.39 | AM26: -1335.54 | AN26: -354.5 | AO26: 8841.82 | AP26: -1853.52 | AQ26: -33091.03 | AR26: -36431.52 | AS26: -15639.86 | AT26: 12993.14 | AU26: 4012.84 | AV26: -19130.57 | AW26: -19148.63 | AX26: 13862.71 | AY26: -4107.92 | AZ26: -1008.16 | BA26: -9852.5 | BB26: -16497.23 | BC26: -18684.8
AH27: -27007.92 | AI27: 2138.35 | AJ27: 10336.97 | AK27: -3864.82 | AL27: -51049.97 | AM27: 4329.54 | AN27: -28785.6 | AO27: -55691.11 | AP27: -41976.79 | AQ27: -12113.12 | AR27: -17833.24 | AS27: 191081.19 | AT27: 16140.16 | AU27: -80455.96 | AV27: 6919.81 | AW27: 26417.2 | AX27: -226613.48 | AY27: -27814.77 | AZ27: 55890.95 | BA27: -107078.05 | BB27: 35728.89 | BC27: 197847.02
AH28: -4101.98 | AI28: 12392.84 | AJ28: 187.53 | AK28: 1051.46 | AL28: 3546.86 | AM28: 5839.29 | AN28: 30378.36 | AO28: 6998.29 | AP28: -9863.51 | AQ28: -8501.72 | AR28: -14036.25 | AS28: -18750.55 | AT28: -1000.37 | AU28: -3137.84 | AV28: -8396.24 | AW28: 6414.38 | AX28: 4562.44 | AY28: 24810.42 | AZ28: 9261.11 | BA28: 11.52 | BB28: -123.38 | BC28: 8265.56
AN30: IRO
B31: Aster | C31: 544682.6 | D31: 1192750 | E31: 0.45666116
B32: AgeCare Brandt's Creek Mews | C32: 0 | D32: 0 | E32: NA | F32: BCM
B33: AgeCare Cariboo Place | C33: 7309.05 | D33: 0 | E33: NA | F33: CPL
B34: AgeCare Monashee Mews | C34: 25408.3 | D34: 3000 | E34: 8.4694333 | F34: MOM
B35: AgeCare Mount Ida Mews | C35: 90307.57 | D35: 160000 | E35: 0.56442231 | F35: MIM
B36: AgeCare Sun Rivers | C36: 50653.65 | D36: 0 | E36: NA | F36: SR
B37: AgeCare Sagewood | C37: 54680.27 | D37: 109750 | E37: 0.49822569 | F37: SW
B38: AgeCare Seton | C38: 69457.45 | D38: 432500 | E38: 0.16059526 | F38: ST
B39: AgeCare SkyPointe | C39: 65021.44 | D39: 69950 | E39: 0.92954167 | F39: SP
B40: AgeCare Sunrise Gardens | C40: 63713.98 | D40: 241850 | E40: 0.2634442 | F40: SRG
B41: AgeCare Walden Heights | C41: 118130.89 | D41: 175700 | E41: 0.67234428 | F41: WH
B42: Bloom | C42: 1392673 | D42: 2710421 | E42: 0.51382167
B43: AgeCare Bow Crest | C43: 44291.55 | D43: 93150 | E43: 0.47548631 | F43: BBC | G43: BBC | H43: 0.47548631
B44: AgeCare Jasper Place | C44: 43879.08 | D44: 74050 | E44: 0.59256016 | F44: BJP | G44: BJP | H44: 0.59256016
B45: AgeCare McKenzie Towne | C45: 125593.56 | D45: 483200 | E45: 0.25992045 | F45: BMT | G45: BMT | H45: 0.25992045
B46: AgeCare Miller Crossing | C46: 164971.93 | D46: 148650 | E46: 1.1098011 | F46: BMC | G46: BMC | H46: 1.1098011
B47: AgeCare Mount Royal | C47: 37955.25 | D47: 75150 | E47: 0.50505988 | F47: BMR | G47: BMR | H47: 0.50505988
B48: AgeCare Riverview | C48: 53306.04 | D48: 417250 | E48: 0.12775564 | F48: BRV | G48: BRV | H48: 0.12775564
B49: AgeCare South Terrace | C49: 34018.38 | D49: 81450 | E49: 0.41765967 | F49: BST | G49: BST | H49: 0.41765967
...

Sheet Aug
B2: Actual | C2: CL | D2: GL | E2: MN | F2: OM | G2: VV | H2: HC | I2: SW | J2: ST | K2: SP | L2: SG | M2: WH | N2: BCM | O2: CPL | P2: MOM | Q2: MIM | R2: SR | S2: BBC | T2: BJP | U2: BMT | V2: BMC | W2: BMR | X2: BRV | Y2: BST | Z2: BGW | AA2: BHR | AB2: BJB | AC2: BLV | AD2: BRC | AE2: BSD | AF2: BCT | AG2: BMS | AH2: IAM | AI2: IAR | AJ2: IEM | AK2: ILD | AL2: IPG | AM2: IPH | AN2: IRO | AO2: ITL | AP2: RBR | AQ2: RGO | AR2: RSM | AS2: RWB | AT2: RWG | AU2: RWH | AV2: RWL | AW2: RWW | AX2: MGS | AY2: MBC | AZ2: MCG | BA2: MQG | BB2: MRG | BC2: MVF
B3: Sick Time | C3: 1349.86 | D3: 35614.57 | E3: 44595.26 | F3: 2135.02 | G3: 11200 | H3: 1969.55 | I3: 15315.11 | J3: 39924.79 | K3: 63433.85 | L3: 9733.13 | M3: 39745.07 | N3: 7866.14 | O3: 4622.94 | P3: 3344.76 | Q3: 15902.96 | R3: 612.9 | S3: 15724.33 | T3: 40212.2 | U3: 19786.85 | V3: 41279.52 | W3: 16837.02 | X3: 19493.13 | Y3: 30321.59 | Z3: 38448.19 | AA3: 18260.32 | AB3: 26824.11 | AC3: 17385.67 | AD3: 39854.25 | AE3: 5216.37 | AF3: 475.14 | AG3: 21.32 | AH3: 11612.56 | AI3: 28199.32 | AJ3: 12450.26 | AK3: 10198.61 | AL3: 21729.01 | AM3: 8243.42 | AN3: 20369.17 | AO3: 18816.39 | AP3: 25141.18 | AQ3: 36450.35 | AR3: 24745.62 | AS3: 34654.05 | AT3: 19624.75 | AU3: 22519.21 | AV3: 17900.5 | AW3: 24605.8 | AX3: 29064.04 | AY3: 14812.62 | AZ3: 25260 | BA3: 16575.92 | BB3: 24933.02 | BC3: 23666.97
B4: Overtime | C4: 1064.75 | D4: 11067.38 | E4: 23115.19 | F4: 1616.24 | G4: 5094.66 | H4: 45.77 | I4: 10221.19 | J4: 4933.52 | K4: 19058.67 | L4: 3572.81 | M4: 14507.74 | N4: 39074.56 | O4: 12949.63 | P4: 4405.05 | Q4: 42271.22 | R4: 0 | S4: 21062.55 | T4: 8697.42 | U4: 11826.02 | V4: 17199.37 | W4: 14413.63 | X4: 22001.4 | Y4: 8760.6 | Z4: 161223.71 | AA4: 23938.34 | AB4: 53094.13 | AC4: 34594.36 | AD4: 28288.34 | AE4: 5484.93 | AF4: 0 | AG4: 0 | AH4: 34558.82 | AI4: 107781.07 | AJ4: 6076.2 | AK4: 36319.86 | AL4: 36357.33 | AM4: 20643.91 | AN4: 92725.26 | AO4: 104740.83 | AP4: 72301.3 | AQ4: 118467.88 | AR4: 108482.18 | AS4: 51650.05 | AT4: 61736.15 | AU4: 168862.52 | AV4: 55570.45 | AW4: 81146.35 | AX4: 43974.7 | AY4: 97668.38 | AZ4: 23753.74 | BA4: 46015.99 | BB4: 57905.49 | BC4: 90478.84
B5: Purchased Hours | C5: 0 | D5: 17978.63 | E5: 50078 | F5: 0 | G5: 2208.28 | H5: 447540.57 | I5: 0 | J5: 16991.5 | K5: 29302.5 | L5: 0 | M5: 2002 | N5: 83487.37 | O5: 167821.06 | P5: 143809.26 | Q5: 199721.63 | R5: 534100.17 | S5: 1682.1 | T5: 5330.56 | U5: 36897.21 | V5: 0 | W5: 0 | X5: 1122.08 | Y5: 278.25 | Z5: 141430.78 | AA5: 136811.32 | AB5: 180311.53 | AC5: 226780.62 | AD5: 35825.98 | AE5: 72531.28 | AF5: 811649.4 | AG5: 860965.96 | AH5: 75300.06 | AI5: 181976.99 | AJ5: 12816.55 | AK5: 27952.19 | AL5: 78241.99 | AM5: 38951.06 | AN5: 182658.32 | AO5: 108006.44 | AP5: 70838.28 | AQ5: 49759.17 | AR5: 172650.59 | AS5: 44416.2 | AT5: 91952.76 | AU5: 239886.62 | AV5: 132544.73 | AW5: 91734.16 | AX5: 72460.6 | AY5: 59875.08 | AZ5: 186862.05 | BA5: 207928.81 | BB5: 35851.44 | BC5: 282134.55
